<?xml version="1.0" ?>
<robot name="my_robot">
  <link name="base_link">
    <inertial>
      <origin rpy="0 0 0" xyz="0 0 0"/>
      <mass value="100.0"/>
      <inertia ixx="1.0" ixy="0.0" ixz="0.0"
              iyy="1.0" iyz="0.0" izz="1.0"/>
    </inertial>
    
    <visual>
      <origin rpy="0 0 0" xyz="0 0 0"/>
      <geometry>
        <box size="0.5 0.5 0.5"/>
      </geometry>
      <material name="white">
        <color rgba="1 1 1 1"/>
      </material>
    </visual>

    <collision>
      <origin rpy="0 0 0" xyz="0 0 0"/>
      <geometry>
        <box size="0.5 0.5 0.5"/>
      </geometry>
    </collision>
  </link>

  <joint name="base_to_body" type="fixed">
    <parent link="base_link"/>
    <child link="body_link"/>
    <origin xyz="0 0 0.6"/>
  </joint>

  <link name="body_link">
    <inertial>
      <origin rpy="0 0 0" xyz="0 0 0"/>
      <mass value="1.0"/>
      <inertia ixx="0.1" ixy="0.0" ixz="0.0"
              iyy="0.1" iyz="0.0" izz="1.0"/>
    </inertial>
    
    <visual>
      <origin rpy="0 0 0" xyz="0 0 0"/>
      <geometry>
        <box size="0.1 0.1 0.8"/>
      </geometry>
      <material name="blue">
        <color rgba="0 0 1 1"/>
      </material>
    </visual>

    <collision>
      <origin rpy="0 0 0" xyz="0 0 0"/>
      <geometry>
        <box size="0.1 0.1 0.8"/>
      </geometry>
    </collision>
  </link>

  <joint name="base_to_top" type="revolute">
    <axis xyz="0 0 1"/>
    <limit lower="-1" upper="1" effort="10.0" velocity="1.0"/>
    <parent link="body_link"/>
    <child link="top_link"/>
    <origin xyz="0.0 0 0.35"/>
    <dynamics damping="0.1" friction="2"/>
  </joint>

  <link name="top_link">
    <inertial>
      <origin xyz="0.4 0 0"/>
      <mass value="1.0"/>
      <inertia ixx="0.1" ixy="0.0" ixz="0.0"
              iyy="0.1" iyz="0.0" izz="1.0"/>
    </inertial>
    
    <visual>
      <origin xyz="0.2 0 0"/>
      <geometry>
        <box size="0.4 0.1 0.1"/>
      </geometry>
      <material name="blue">
        <color rgba="0 0 1 1"/>
      </material>
    </visual>

    <collision>
     <origin xyz="0 0 0"/>
      <geometry>
        <box size="0.4 0.1 0.1"/>
      </geometry>
    </collision>
  </link>

</robot>
